Workbook

Sheet 작성안내
A1: 수원도시공사 사업장 안내 지도 — 사업장 정보 입력 양식
A2: 문서 버전: v0.4 / 작성일: 2026-10-29 / 기준 자료: 수원도시공사 공식 홈페이지(사업현황·시설별 홈페이지·공영주차장 통합홈페이지)
A4: 1. 시트 구성
A5: 사업장목록 | B5: 시설·서비스 1건당 1행. 지도 마커와 하단 패널에 표시되는 원본 데이터입니다.
A6: 공영주차장 | B6: 공영주차장 통합홈페이지에 등록된 69개소(위도·경도 포함). 지도의 '주차하기' 레이어 원본입니다.
A7: 진행현황 | B7: 검증 상태·분류·주차장 구분별 건수를 자동 집계합니다. 직접 수정하지 않습니다.
A8: 분류코드 | B8: 드롭다운 선택값을 관리합니다. 분류를 추가하려면 이 시트에 행을 추가합니다.
A9: 변경내역 | B9: v0.1 → v0.2에서 바뀐 내용입니다.
A10: 출처목록 | B10: 입력값의 근거 자료와 확인일입니다.
A12: 2. 입력 규칙
A13: 입력 셀 | B13: 연노랑 셀이 입력 대상입니다. 진행현황 시트의 수식 셀은 수정하지 않습니다.
A14: 예시 행 | B14: 사업장목록 SUDC-001(장안구민회관) 행을 작성 예시로 참고합니다.
A15: 날짜·전화 | B15: 날짜는 YYYY-MM-DD, 전화번호는 031-000-0000 형식으로 통일합니다.
A16: 하는 일 | B16: 시민이 읽는 한 줄 소개(40자 내외). 사전 입력 문구는 각 시설 홈페이지 메뉴 구성을 근거로 작성한 초안이므로 시설 담당 부서 확인이 필요합니다.
A17: 지도 표시 방식 | B17: 시설 마커 = 지도에 건물로 표시 / 레이어 = 개소가 많아 켜고 끄는 마커 묶음 / 서비스 안내 = 방문 시설이 아니어서 패널 카드로만 안내
A18: 일러스트 등급 | B18: A = 개별 3D 건물 일러스트 / B = 공통 블록 아이콘 / - = 지도에 그리지 않음
A19: 지도 위치 X·Y | B19: 일러스트 지도 위 배치 좌표(0~100, 왼쪽 위 기준). 일러스트 확정 후 입력합니다. 실제 위도·경도와는 다릅니다.
A20: 담당자 표기 | B20: 실명 대신 '담당자 A/B' 또는 '직책+역할' 형식으로 입력합니다.
A22: 3. 검증 상태 기준
A23: 확인완료 | B23: 공사 내부 자료 또는 시설 담당 부서로 사실 확인을 마친 상태
A24: 홈페이지 확인 | B24: 공사 공식 홈페이지 값과 일치하며 다른 출처와 상충이 없는 상태 (내부 확인 전)
A25: 확인 필요 | B25: 출처 간 값이 다르거나(두 값 병기), 공사 홈페이지 외 출처만 있는 상태
A26: 출처 미확인 | B26: 값은 있으나 근거 문서를 특정할 수 없는 상태
A27: 미입력 | B27: 아직 값이 없는 상태
A29: 4. 주의사항
A30: 주차장 면수 | B30: 공영주차장 시트의 면수·충전기 수는 2026-10-29 통합홈페이지 조회값입니다. 운영 중 바뀔 수 있습니다.
A31: 좌표 정밀도 | B31: 소수점 4자리 이하로 등록된 좌표는 실제 위치와 수십 m 이상 차이 날 수 있어 '확인 필요'로 표시했습니다.
A32: 지도 범위 | B32: 화산체육공원은 화성시에 있어 수원시 일러스트 지도 범위 밖입니다. 표시 방식 결정이 필요합니다.

Sheet 사업장목록
A1: 코드 | B1: 사업장명 | C1: 공사 공식 분류 | D1: 생활목적 분류 | E1: 세부 유형 | F1: 지도 표시 방식 | G1: 구 | H1: 도로명주소 | I1: 우편번호 | J1: 대표전화 | K1: 보조 연락처 | L1: 운영시간 | M1: 휴관일 | N1: 하는 일(한 줄 소개) | O1: 주요 시설·프로그램 | P1: 홈페이지 URL | Q1: 카카오맵 링크 | R1: 일러스트 등급 | S1: 지도 위치 X | T1: 지도 위치 Y | U1: 사진 확보 | V1: 데이터 출처 | W1: 자료 시점 | X1: 검증 상태 | Y1: 입력 담당 | Z1: 최종 수정일 | AA1: 비고
A2: SUDC-001 | B2: 장안구민회관 | C2: 문화·체육 | D2: 운동·배우기 | E2: 구민회관(평생교육·체육·공연) | F2: 시설 마커 | G2: 장안구 | H2: 경기도 수원시 장안구 송원로 101 (조원동) | I2: 16295 | J2: 031-228-3001~3003 | K2: ARS 031-228-3000 | L2: 평일 06:00~22:00 / 토 09:00~18:00 / 일 10:00~17:00 | M2: 둘째·넷째 일요일 | N2: 평생교육 강좌와 수영·헬스·스쿼시, 공연·전시를 운영하는 구민회관 | O2: 평생교육·문화교육 강좌, 수영장(푸르내수영장)·헬스·스쿼시, 한누리아트홀 공연·전시, 대관, 늘봄어르신 | P2: https://www.suwonudc.co.kr/jacc/mainPage.do | Q2: http://place.map.kakao.com/8504713 | R2: A | V2: 공사 홈페이지(시설 홈페이지 하단·사업현황), 카카오맵, 기획팀장 확인(2026-10-29), 운영시간·휴관일: 기획팀장 확인(2026-10-29) | W2: 2026-10-29 | X2: 확인완료 | Y2: 담당자 A | Z2: 2026-10-29 | AA2: [작성 예시 행] 대표전화 확정(기획팀장 확인 2026-10-29). 수원시 자료의 031-240-3014·031-228-3014는 사용하지 않음
A3: SUDC-002 | B3: 수원종합운동장 | C3: 문화·체육 | D3: 운동·배우기 | E3: 종합운동장 | F3: 시설 마커 | G3: 장안구 | H3: 경기도 수원시 장안구 경수대로 893 | I3: 16308 | J3: 031-228-2700 (수원체육관) | K3: 국민체육센터 031-228-2701 | L3: 경기·행사별 상이(홈페이지 월간일정표 참고) | M3: 경기·행사별 상이 | N3: 주경기장·야구장·체육관 등 경기장과 국민체육센터를 운영하는 종합운동장 | O3: 주경기장, 야구장, 수원체육관, 국민체육센터, 인조잔디구장, 야외농구장, 리틀야구장, 대관 | P3: https://www.suwonudc.co.kr/suwonsc/mainPage.do | Q3: http://place.map.kakao.com/7958665 | R3: A | V3: 공사 홈페이지(시설 홈페이지 하단·사업현황), 카카오맵, 기획팀장 확인(2026-10-29), 운영시간·휴관일: 기획팀장 확인(2026-10-29) | W3: 2026-10-29 | X3: 확인완료 | Z3: 2026-10-29 | AA3: 국민체육센터 전화 031-228-2701로 확정(기획팀장 확인 2026-10-29). 공영주차장 주차관리팀 사무실도 같은 주소(주경기장 1층)
A4: SUDC-003 | B4: 서수원칠보체육관 | C4: 문화·체육 | D4: 운동·배우기 | E4: 체육관·스포츠센터 | F4: 시설 마커 | G4: 권선구 | H4: 경기도 수원시 권선구 서수원로577번길 171 | I4: 16389 | J4: 031-228-2600 | L4: 주중 06:10~21:30 / 주말 09:10~17:40 | M4: 둘째·넷째 일요일, 법정공휴일, 공사 지정 휴무일 | N4: 실내체육관 대관과 헬스·요가·GX·탁구 스포츠센터, 야외 체육시설을 운영 | O4: 실내체육관, 헬스장, 요가전용실, GX룸, 탁구장, 인조잔디구장, 야외농구장, 야외배드민턴장, 게이트볼장, 파크골프장 | P4: https://www.suwonudc.co.kr/suwonsc2/mainPage.do | Q4: http://place.map.kakao.com/26174144 | R4: A | V4: 공사 홈페이지(시설 홈페이지 하단·사업현황), 카카오맵, 수원시 통합예약(탁구장), 기획팀장 확인(2026-10-29) | W4: 2026-10-29 | X4: 확인완료 | Z4: 2026-10-29 | AA4: 대표전화 031-228-2600으로 확정(기획팀장 확인 2026-10-29). 운영시간·휴관일은 수원시 통합예약 탁구장 안내 기준
A5: SUDC-004 | B5: 광교웰빙국민체육센터 | C5: 문화·체육 | D5: 운동·배우기 | E5: 국민체육센터 | F5: 시설 마커 | G5: 영통구 | H5: 경기도 수원시 영통구 웰빙타운로 71 (이의동) | I5: 16222 | J5: 031-228-3200~3 | L5: 시설 홈페이지 참고 | M5: 시설 홈페이지 참고 | N5: 수영장과 GX룸·다목적체육관·당구장을 운영하는 국민체육센터 | O5: 수영장, GX룸, 다목적체육관, 다목적구장, 당구장, 인터넷 수강신청 | P5: https://www.suwonudc.co.kr/suwonsc3/mainPage.do | Q5: http://place.map.kakao.com/338452642 | R5: A | V5: 공사 홈페이지(시설 홈페이지 하단·사업현황), 카카오맵, 수원시 체육시설 현황, 기획팀장 확인(2026-10-29), 운영시간·휴관일: 기획팀장 확인(2026-10-29) | W5: 2026-10-29 | X5: 확인완료 | Z5: 2026-10-29 | AA5: 주소·전화 확정(기획팀장 확인 2026-10-29). 내부 호칭 '웰빙스포츠센터'와 같은 시설
A6: SUDC-005 | B6: 화산체육공원 | C6: 문화·체육 | D6: 운동·배우기 | E6: 체육공원(골프연습장·Par-3) | F6: 시설 마커 | G6: 수원시 외 | H6: 경기도 화성시 병점구 태안로 263 (수원생태수자원센터 내) | I6: 18358 | J6: 031-228-3100 | L6: Par-3 9홀: 하절기(4~10월) 07:00~18:00 / 동절기(11~3월) 08:00~17:00 | M6: 매월 마지막 월요일 | N6: 골프연습장·Par-3 9홀과 구기·인라인 시설을 갖춘 체육공원 | O6: 골프연습장, Par-3 9홀, 골프아카데미, 인조잔디구장, 테니스장, 농구장, 족구장, 인라인스케이트장, 생태공원 | P6: https://www.suwonudc.co.kr/hwasanap/mainPage.do | Q6: http://place.map.kakao.com/11495451 | R6: A | V6: 공사 홈페이지(시설 홈페이지 하단·사업현황), 카카오맵, 공사 홈페이지 공지(2026-10-23), 운영시간·휴관일: 기획팀장 확인(2026-10-29) | W6: 2026-10-23 | X6: 홈페이지 확인 | Z6: 2026-10-29 | AA6: 소재지가 화성시로 수원시 지도 범위 밖 — 표시 방식 결정 필요. Par-3 9홀 2026-10-24 재개장. 운영시간은 Par-3 기준이며 골프연습장 등 다른 시설 시간은 미입력
A7: SUDC-006 | B7: 광교호수가족캠핑장 | C7: 문화·체육 | D7: 캠핑·여가 | E7: 가족캠핑장 | F7: 시설 마커 | G7: 영통구 | H7: 경기도 수원시 영통구 광교호수로 57 (하동) | I7: 16514 | J7: 031-548-0075 | L7: 입실 이용 당일 14:00 ~ 퇴실 다음 날 11:00 | M7: 매월 마지막 주 월요일(월요일이 공휴일이면 다음 날) | N7: 광교호수공원 안에서 가족 단위 캠핑장을 예약제로 운영 | O7: 캠핑 사이트, 온라인 예약, 주변 볼거리 안내 | P7: https://www.suwonudc.co.kr/ggcamping/mainPage.do | Q7: http://place.map.kakao.com/22377944 | R7: A | V7: 공사 홈페이지(시설 홈페이지 하단·사업현황), 카카오맵, 운영시간·휴관일: 기획팀장 확인(2026-10-29) | W7: 2026-10-29 | X7: 홈페이지 확인 | Z7: 2026-10-29
A8: SUDC-007 | B8: 수원시가족여성회관 | C8: 문화·체육 | D8: 운동·배우기 | E8: 여성·가족 교육시설 | F8: 시설 마커 | G8: 팔달구 | H8: 경기도 수원시 팔달구 매산로 119 (교동) | I8: 16463 | J8: 031-228-3300~1 | L8: 09:00~21:00 | M8: 매주 일요일, 공휴일 | N8: 양성평등 교육과 정규 교육강좌, 대관을 운영하는 여성·가족 교육시설 | O8: 젠더아카데미, 찾아가는 양성평등 교육, 정규교육강좌, 기획프로그램, 대관, 전시관(기억의 방) | P8: https://www.suwonudc.co.kr/sfwomen/mainPage.do | Q8: http://place.map.kakao.com/7967131 | R8: A | V8: 공사 홈페이지(시설 홈페이지 하단·사업현황), 카카오맵, 운영시간·휴관일: 기획팀장 확인(2026-10-29) | W8: 2026-10-29 | X8: 홈페이지 확인 | Z8: 2026-10-29
A9: SUDC-008 | B9: 수원시연화장 | C9: 생활·복지 | D9: 장례·추모 | E9: 공설 장사시설 | F9: 시설 마커 | G9: 영통구 | H9: 경기도 수원시 영통구 광교호수로 278 | I9: 16511 | J9: 031-228-2400 | K9: 장례식장 접수 031-228-2401 | L9: 승화원 매일 07:00~16:00 / 장례식장 24시간 | M9: 연중무휴 | N9: 화장(승화원)·장례식장·봉안시설을 운영하는 공설 장사시설 | O9: 승화원(화장장), 장례식장, 추모의집·봉안담·자연장, 온라인추모관, 실시간 빈소현황 | P9: https://www.suwonudc.co.kr/suwonyhj/mainPage.do | Q9: http://place.map.kakao.com/12450770 | R9: A | V9: 공사 홈페이지(시설 홈페이지 하단·사업현황), 카카오맵, 운영시간·휴관일: 기획팀장 확인(2026-10-29) | W9: 2026-10-29 | X9: 홈페이지 확인 | Z9: 2026-10-29
A10: SUDC-009 | B10: 수원시장기요양지원센터 | C10: 생활·복지 | D10: 돌봄·복지 | E10: 장기요양 지원기관 | F10: 시설 마커 | G10: 팔달구 | H10: 경기도 수원시 팔달구 경수대로 612 | I10: 16240 | J10: 031-228-3420 | L10: 평일 09:00~18:00 | M10: 주말·공휴일 | N10: 노인장기요양 정보 안내와 상담, 요양보호사 등 종사자 교육을 지원 | O10: 장기요양 상담, 요양보호사 보수교육, 장애인활동지원사 교육, 장기요양기관 안내 | P10: https://www.suwonudc.co.kr/swjjc/base/main/view | Q10: http://place.map.kakao.com/9162799 | R10: A | V10: 공사 홈페이지(시설 홈페이지 하단·사업현황), 카카오맵, 운영시간·휴관일: 기획팀장 확인(2026-10-29) | W10: 2026-10-29 | X10: 홈페이지 확인 | Z10: 2026-10-29
A11: SUDC-010 | B11: 한아름콜센터 | C11: 생활·복지 | D11: 이동 지원 | E11: 교통약자 이동지원 | F11: 서비스 안내 | G11: 권선구 | H11: 경기도 수원시 권선구 정조로 310 | I11: 16661 | J11: 031-253-5525 | L11: 24시간 | M11: 연중무휴 | N11: 장애인 등 교통약자를 위한 이동 차량 서비스를 운영 | O11: 운영차량 안내, 이용기준, 이용자 등록, 이용방법 | P11: https://www.suwonudc.co.kr/swcall/mainPage.do | Q11: http://place.map.kakao.com/11894050 | R11: - | V11: 공사 홈페이지(시설 홈페이지 하단·사업현황), 카카오맵, 운영시간·휴관일: 기획팀장 확인(2026-10-29) | W11: 2026-10-29 | X11: 홈페이지 확인 | Z11: 2026-10-29 | AA11: 시민이 방문하는 시설이 아니므로 마커 대신 서비스 안내 카드로 표시 권장
A12: SUDC-011 | B12: 수원시자원순환센터 | C12: 생활·복지 | D12: 환경·자원순환 | E12: 재활용·종량제봉투 | F12: 시설 마커 | G12: 영통구 | H12: 경기도 수원시 영통구 광교호수로 278-1 (하동) | I12: 16511 | J12: 031-228-2512 | K12: 종량제봉투 전화주문 031-228-2500 | L12: 평일 09:00~18:00 | M12: 주말·공휴일 | N12: 생활폐기물 반입과 재활용품 선별·매각, 종량제봉투 공급을 담당 | O12: 생활폐기물 수집·반입, 재활용품 매각, 종량제봉투 주문·판매소 안내 | P12: https://www.suwonudc.co.kr/recycle/mainPage.do | Q12: http://place.map.kakao.com/24662855 | R12: B | V12: 공사 홈페이지(시설 홈페이지 하단·사업현황), 카카오맵, 운영시간·휴관일: 기획팀장 확인(2026-10-29) | W12: 2026-10-29 | X12: 홈페이지 확인 | Z12: 2026-10-29
A13: SUDC-012 | B13: 공영주차장(69개소) | C13: 주차·교통 | D13: 주차하기 | E13: 공영·부설 주차장 | F13: 레이어 | G13: 여러 구 | H13: 사무실: 경기도 수원시 장안구 경수대로 893 주경기장 1층 주차관리팀 | I13: 16308 | J13: 031-228-2000 | L13: 주차장별 상이(통합홈페이지 참고) | M13: 주차장별 상이 | N13: 공영·부설 주차장 69개소와 사전결제·정기권 온라인 서비스를 운영 | O13: 개소별 상세는 '공영주차장' 시트 참조 | P13: https://parking.suwonudc.co.kr/ | R13: B | V13: 공사 공영주차장 통합홈페이지, 운영시간·휴관일: 기획팀장 확인(2026-10-29) | W13: 2026-10-29 | X13: 홈페이지 확인 | Z13: 2026-10-29 | AA13: v0.1의 '2019년 기준 45곳'을 2026-10-29 통합홈페이지 등록 69개소로 대체
A14: SUDC-013 | B14: 거주자우선주차·견인보관소 | C14: 주차·교통 | D14: 주차하기 | E14: 거주자우선주차·견인 | F14: 서비스 안내 | G14: 권선구 | H14: 경기도 수원시 권선구 정조로 304 (거주자견인팀) | I14: 16661 | J14: 031-238-0560 | L14: 시설 홈페이지 참고 | M14: 시설 홈페이지 참고 | N14: 거주자 우선주차 배정과 견인차량 보관을 담당 | O14: 거주자우선주차 신청, 견인차량 보관·반환 | P14: http://www.suwonpark.co.kr | R14: - | V14: 공사 홈페이지(시설 홈페이지 하단·사업현황), 카카오맵, 운영시간·휴관일: 기획팀장 확인(2026-10-29) | W14: 2026-10-29 | X14: 홈페이지 확인 | Z14: 2026-10-29 | AA14: 견인보관소를 방문 시설로 마커 표시할지 결정 필요
A15: SUDC-014 | B15: 번호판제작소 | C15: 주차·교통 | D15: 교통·차량 서비스 | E15: 자동차 번호판 교부 | F15: 시설 마커 | G15: 권선구 | H15: 경기도 수원시 권선구 서부로 1600 | J15: 031-278-5909 | L15: 평일 09:00~18:00 | M15: 주말·공휴일 | N15: 자동차 번호판 신규·재교부와 탈부착 업무를 처리 | O15: 본소(신규·재교부·탈부착), SK분소·도이치분소(해당 자동차민원실 등록차량 한정) | P15: https://www.suwonudc.co.kr/park/PageLink.do?link=forward:/PageContent.do&menuNo=040000&subMenuNo=040100&thirdMenuNo= | Q15: http://place.map.kakao.com/1568767261 | R15: B | V15: 공사 홈페이지(번호판제작소 현황), 카카오맵, 기획팀장 확인(2026-10-29), 운영시간·휴관일: 기획팀장 확인(2026-10-29) | W15: 2026-10-29 | X15: 확인완료 | Z15: 2026-10-29 | AA15: 주소·전화 확정(기획팀장 확인 2026-10-29). 본소 1곳만 지도 표시
A16: SUDC-015 | B16: 수원역환승센터 | C16: 주차·교통 | D16: 교통·차량 서비스 | E16: 환승센터 | F16: 시설 마커 | G16: 권선구 | H16: 경기도 수원시 권선구 세화로 136 | I16: 16621 | J16: 031-228-2300 | L16: 시설 홈페이지 참고 | M16: 시설 홈페이지 참고 | N16: 수원역 버스·철도 환승을 위한 환승센터를 운영 | O16: 환승센터 운영 | P16: https://www.suwonudc.co.kr/swtraffic/mainPage.do | Q16: http://place.map.kakao.com/27488516 | R16: B | V16: 공사 홈페이지(시설 홈페이지 하단·사업현황), 카카오맵, 운영시간·휴관일: 기획팀장 확인(2026-10-29) | W16: 2026-10-29 | X16: 홈페이지 확인 | Z16: 2026-10-29
A17: SUDC-016 | B17: 광교중앙역환승센터 | C17: 주차·교통 | D17: 교통·차량 서비스 | E17: 환승센터 | F17: 시설 마커 | G17: 영통구 | H17: 경기도 수원시 영통구 도청로 지하 45 | J17: 031-228-2300 (환승센터 대표) | L17: 시설 홈페이지 참고 | M17: 시설 홈페이지 참고 | N17: 광교중앙역 버스 환승센터를 운영 | O17: 환승센터 운영 | P17: https://www.suwonudc.co.kr/swtraffic/mainPage.do | Q17: http://place.map.kakao.com/319339301 | R17: B | V17: 공사 홈페이지(환승센터 메뉴), 카카오맵, 기획팀장 확인(2026-10-29), 운영시간·휴관일: 기획팀장 확인(2026-10-29) | W17: 2026-10-29 | X17: 확인완료 | Z17: 2026-10-29 | AA17: 주소 확정(기획팀장 확인 2026-10-29, 카카오맵 기준)
A18: SUDC-017 | B18: 수원도시공사 본사(더함파크) | C18: 공사 본사 | D18: 공사 본사·개발사업 | E18: 본사 사옥 | F18: 시설 마커 | G18: 권선구 | H18: 경기도 수원시 권선구 수인로 126 더함파크 3층 | I18: 16429 | J18: 031-228-2800 | L18: 평일 09:00~18:00 | M18: 주말·공휴일 | N18: 공사 경영 전반을 맡는 본사가 있는 사옥 | O18: 민원 접수, 채용·정보공개 안내 | P18: https://www.suwonudc.co.kr/mainPage.do | Q18: http://place.map.kakao.com/896850716 | R18: A | V18: 공사 홈페이지 하단, 카카오맵, 운영시간·휴관일: 기획팀장 확인(2026-10-29) | W18: 2026-10-29 | X18: 홈페이지 확인 | Z18: 2026-10-29 | AA18: v0.1의 '더함파크' 행은 본사 건물로 확인되어 이 행으로 통합
A19: SUDC-018 | B19: 개발사업본부 | C19: 개발사업 | D19: 공사 본사·개발사업 | E19: 개발사업 | F19: 서비스 안내 | G19: 권선구 | H19: 경기도 수원시 권선구 수인로 126 더함파크 3층 | I19: 16429 | J19: 031-228-2917 | L19: 평일 09:00~18:00 | M19: 주말·공휴일 | N19: 도시개발·주택건설·도시정비·위수탁개발 사업을 시행 | O19: 탑동이노베이션밸리(탑동IV), 도시개발사업, 주택건설사업, 도시정비사업, 위수탁개발사업 | P19: https://www.suwonudc.co.kr/swdevelop/mainPage.do | R19: - | V19: 공사 홈페이지(시설 홈페이지 하단·사업현황), 카카오맵, 운영시간·휴관일: 기획팀장 확인(2026-10-29) | W19: 2026-10-29 | X19: 홈페이지 확인 | Z19: 2026-10-29 | AA19: 사업지구(탑동 등) 위치를 지도에 별도 표시할지 결정 필요

Sheet 공영주차장
A1: 코드 | B1: 주차장ID | C1: 주차장명 | D1: 구분 | E1: 운영 표기 | F1: 총 면수 | G1: 급속 충전기 | H1: 완속 충전기 | I1: 위도 | J1: 경도 | K1: 좌표 정밀도 | L1: 실시간 연동 | M1: 도로명주소 | N1: 구 | O1: 일러스트 마커 | P1: 검증 상태 | Q1: 비고
A2: P-001 | B2: 10400 | C2: 성대 환승(구) | D2: 공영 | E2: 수원도시공사 | F2: 160 | G2: 0 | H2: 3 | I2: 37.3007 | J2: 126.9712 | K2: 낮음(소수 4자리 이하) | L2: 연동 | O2: B | P2: 확인 필요 | Q2: 좌표 재확인 필요.
A3: P-002 | B3: 10600 | C3: 꽃뫼환승 | D3: 공영 | E3: 수원도시공사 | F3: 136 | G3: 2 | H3: 3 | I3: 37.2852 | J3: 126.987 | K3: 낮음(소수 4자리 이하) | L3: 연동 | O3: B | P3: 확인 필요 | Q3: 좌표 재확인 필요.
A4: P-003 | B4: 10800 | C4: 세류역환승 | D4: 공영 | E4: 수원도시공사 | F4: 136 | G4: 2 | H4: 2 | I4: 37.242364 | J4: 127.01487 | K4: 양호 | L4: 연동 | O4: B | P4: 홈페이지 확인
A5: P-004 | B5: 11100 | C5: 성균관대역 환승 | D5: 공영 | E5: 수원도시공사 | F5: 191 | G5: 4 | H5: 6 | I5: 37.3 | J5: 126.9705 | K5: 낮음(소수 4자리 이하) | L5: 연동 | O5: B | P5: 확인 필요 | Q5: 좌표 재확인 필요.
A6: P-005 | B6: 20200 | C6: 교동 공영 | D6: 공영 | E6: 수원도시공사 | F6: 243 | G6: 6 | H6: 6 | I6: 37.273213 | J6: 127.01535 | K6: 양호 | L6: 연동 | O6: B | P6: 홈페이지 확인
A7: P-006 | B7: 20400 | C7: 인계 공영 | D7: 공영 | E7: 수원도시공사 | F7: 56 | G7: 0 | H7: 1 | I7: 37.27485 | J7: 127.0305 | K7: 낮음(소수 4자리 이하) | L7: 연동 | O7: B | P7: 확인 필요 | Q7: 좌표 재확인 필요.
A8: P-007 | B8: 20600 | C8: 영통 공영 | D8: 공영 | E8: 수원도시공사 | F8: 305 | G8: 2 | H8: 4 | I8: 37.253205 | J8: 127.0742 | K8: 양호 | L8: 연동 | O8: B | P8: 홈페이지 확인
A9: P-008 | B9: 21000 | C9: 대황교화물 | D9: 현장운영 | E9: 수원도시공사(현장운영) | F9: 244 | G9: 2 | H9: 3 | I9: 37.230519 | J9: 127.02188 | K9: 양호 | L9: 미연동(현장운영) | O9: B | P9: 홈페이지 확인
A10: P-009 | B10: 21400 | C10: 율전 공영 | D10: 공영 | E10: 수원도시공사 | F10: 72 | G10: 1 | H10: 0 | I10: 37.298 | J10: 126.9713 | K10: 낮음(소수 4자리 이하) | L10: 연동 | O10: B | P10: 확인 필요 | Q10: 좌표 재확인 필요.
A11: P-010 | B11: 21401 | C11: 율전 제2공영 | D11: 공영 | E11: 수원도시공사 | F11: 46 | G11: 0 | H11: 0 | I11: 37.296113 | J11: 126.9703 | K11: 낮음(소수 4자리 이하) | L11: 연동 | O11: B | P11: 확인 필요 | Q11: 좌표 재확인 필요.
A12: P-011 | B12: 21600 | C12: 광교 공영 | D12: 공영 | E12: 수원도시공사 | F12: 360 | G12: 2 | H12: 5 | I12: 37.301315 | J12: 127.03079 | K12: 양호 | L12: 연동 | O12: B | P12: 홈페이지 확인
A13: P-012 | B13: 22000 | C13: 터미널 공영 | D13: 공영 | E13: 수원도시공사 | F13: 51 | G13: 0 | H13: 0 | I13: 37.2495 | J13: 127.02 | K13: 낮음(소수 4자리 이하) | L13: 연동 | O13: B | P13: 확인 필요 | Q13: 좌표 재확인 필요.
A14: P-013 | B14: 22200 | C14: 영화동 지하 | D14: 공영 | E14: 수원도시공사 | F14: 182 | G14: 3 | H14: 1 | I14: 37.293153 | J14: 127.01412 | K14: 양호 | L14: 연동 | O14: B | P14: 홈페이지 확인
A15: P-014 | B15: 22201 | C15: 영화동 지상 | D15: 공영 | E15: 수원도시공사 | F15: 30 | G15: 2 | H15: 5 | I15: 37.292789 | J15: 127.01426 | K15: 양호 | L15: 연동 | O15: B | P15: 홈페이지 확인
A16: P-015 | B16: 22400 | C16: 인계동주택가 공영 | D16: 공영 | E16: 수원도시공사 | F16: 80 | G16: 2 | H16: 0 | I16: 37.271188 | J16: 127.02451 | K16: 양호 | L16: 연동 | O16: B | P16: 홈페이지 확인
A17: P-016 | B17: 22800 | C17: 만석 5주차장 | D17: 공영 | E17: 수원도시공사 | F17: 104 | G17: 2 | H17: 0 | I17: 37.2973 | J17: 126.9998 | K17: 낮음(소수 4자리 이하) | L17: 연동 | O17: B | P17: 확인 필요 | Q17: 좌표 재확인 필요.
A18: P-017 | B18: 23200 | C18: 곡반정동 제2공영 | D18: 공영 | E18: 수원도시공사 | F18: 204 | G18: 3 | H18: 1 | I18: 37.239524 | J18: 127.03063 | K18: 양호 | L18: 연동 | O18: B | P18: 홈페이지 확인
A19: P-018 | B19: 23800 | C19: 백설 공영 | D19: 공영 | E19: 수원도시공사 | F19: 56 | G19: 0 | H19: 2 | I19: 37.295844 | J19: 126.99224 | K19: 양호 | L19: 연동 | O19: B | P19: 홈페이지 확인
A20: P-019 | B20: 24000 | C20: 권선동지하 공영 | D20: 공영 | E20: 수원도시공사 | F20: 66 | G20: 2 | H20: 0 | I20: 37.259191 | J20: 127.01887 | K20: 양호 | L20: 연동 | O20: B | P20: 홈페이지 확인
A21: P-020 | B21: 24200 | C21: 매봉 공영 | D21: 공영 | E21: 수원도시공사 | F21: 200 | G21: 2 | H21: 8 | I21: 37.270166 | J21: 127.05517 | K21: 양호 | L21: 연동 | O21: B | P21: 홈페이지 확인
A22: P-021 | B22: 24400 | C22: 우만공원 공영 | D22: 공영 | E22: 수원도시공사 | F22: 119 | G22: 2 | H22: 0 | I22: 37.286698 | J22: 127.03282 | K22: 양호 | L22: 연동 | O22: B | P22: 홈페이지 확인
A23: P-022 | B23: 24600 | C23: 매탄공원 공영 | D23: 공영 | E23: 수원도시공사 | F23: 222 | G23: 2 | H23: 2 | I23: 37.267133 | J23: 127.04548 | K23: 양호 | L23: 연동 | O23: B | P23: 홈페이지 확인
A24: P-023 | B24: 24800 | C24: 화홍문 공영 | D24: 공영 | E24: 수원도시공사 | F24: 497 | G24: 0 | H24: 0 | I24: 37.289612 | J24: 127.01626 | K24: 양호 | L24: 연동 | O24: B | P24: 홈페이지 확인
A25: P-024 | B25: 25000 | C25: 광교 원천호수 | D25: 공영 | E25: 수원도시공사 | F25: 396 | G25: 8 | H25: 4 | I25: 37.2766 | J25: 127.0662 | K25: 낮음(소수 4자리 이하) | L25: 연동 | O25: B | P25: 확인 필요 | Q25: 좌표 재확인 필요.
A26: P-025 | B26: 25200 | C26: 창룡 공영 | D26: 공영 | E26: 수원도시공사 | F26: 87 | G26: 2 | H26: 0 | I26: 37.291344 | J26: 127.028 | K26: 양호 | L26: 연동 | O26: B | P26: 홈페이지 확인
A27: P-026 | B27: 25400 | C27: 광교 행복한들 | D27: 공영 | E27: 수원도시공사 | F27: 229 | G27: 11 | H27: 0 | I27: 37.281 | J27: 127.069 | K27: 낮음(소수 4자리 이하) | L27: 연동 | O27: B | P27: 확인 필요 | Q27: 좌표 재확인 필요.
A28: P-027 | B28: 25600 | C28: 신대호수 | D28: 공영 | E28: 수원도시공사 | F28: 245 | G28: 6 | H28: 6 | I28: 37.284484 | J28: 127.0774 | K28: 양호 | L28: 연동 | O28: B | P28: 홈페이지 확인
A29: P-028 | B29: 25800 | C29: 광교 카페거리1 공영 | D29: 공영 | E29: 수원도시공사 | F29: 64 | G29: 1 | H29: 0 | I29: 37.29424 | J29: 127.05171 | K29: 양호 | L29: 연동 | O29: B | P29: 홈페이지 확인
A30: P-029 | B30: 26000 | C30: 광교중앙마을 | D30: 공영 | E30: 수원도시공사 | F30: 46 | G30: 0 | H30: 0 | I30: 37.2777 | J30: 127.0503 | K30: 낮음(소수 4자리 이하) | L30: 연동 | O30: B | P30: 확인 필요 | Q30: 좌표 재확인 필요.
A31: P-030 | B31: 26200 | C31: 광교대학로 제2공영 | D31: 공영 | E31: 수원도시공사 | F31: 35 | G31: 0 | H31: 0 | I31: 37.298421 | J31: 127.04366 | K31: 양호 | L31: 연동 | O31: B | P31: 홈페이지 확인
A32: P-031 | B32: 26400 | C32: 광교대학로 제1공영 | D32: 공영 | E32: 수원도시공사 | F32: 50 | G32: 1 | H32: 0 | I32: 37.299157 | J32: 127.04421 | K32: 양호 | L32: 연동 | O32: B | P32: 홈페이지 확인
A33: P-032 | B33: 26600 | C33: 장안동 공영 | D33: 공영 | E33: 수원도시공사 | F33: 163 | G33: 0 | H33: 0 | I33: 37.286536 | J33: 127.01439 | K33: 양호 | L33: 연동 | O33: B | P33: 홈페이지 확인
A34: P-033 | B34: 26800 | C34: 만석 1주차장 | D34: 공영 | E34: 수원도시공사 | F34: 76 | G34: 3 | H34: 0 | I34: 37.301889 | J34: 126.99853 | K34: 양호 | L34: 연동 | O34: B | P34: 홈페이지 확인
A35: P-034 | B35: 26801 | C35: 만석 2주차장 | D35: 공영 | E35: 수원도시공사 | F35: 61 | G35: 1 | H35: 0 | I35: 37.302503 | J35: 127.00235 | K35: 양호 | L35: 연동 | O35: B | P35: 홈페이지 확인
A36: P-035 | B36: 26802 | C36: 만석 3주차장 | D36: 공영 | E36: 수원도시공사 | F36: 50 | G36: 1 | H36: 0 | I36: 37.30147 | J36: 127.00377 | K36: 양호 | L36: 연동 | O36: B | P36: 홈페이지 확인
A37: P-036 | B37: 26803 | C37: 만석 4주차장 | D37: 공영 | E37: 수원도시공사 | F37: 43 | G37: 0 | H37: 0 | I37: 37.2996 | J37: 127.0045 | K37: 낮음(소수 4자리 이하) | L37: 연동 | O37: B | P37: 확인 필요 | Q37: 좌표 재확인 필요.
A38: P-037 | B38: 27000 | C38: 연무동 공영 | D38: 공영 | E38: 수원도시공사 | F38: 158 | G38: 4 | H38: 0 | I38: 37.287784 | J38: 127.02053 | K38: 양호 | L38: 연동 | O38: B | P38: 홈페이지 확인
A39: P-038 | B39: 30400 | C39: 농수산물도매시장 | D39: 현장운영 | E39: 수원도시공사(현장운영) | F39: 748 | G39: 13 | H39: 3 | I39: 37.254988 | J39: 127.03206 | K39: 양호 | L39: 미연동(현장운영) | O39: B | P39: 홈페이지 확인
A40: P-039 | B40: 30800 | C40: 수원시청 본관 | D40: 부설 | E40: 수원도시공사 | F40: 91 | G40: 5 | H40: 0 | I40: 37.262944 | J40: 127.02844 | K40: 양호 | L40: 연동 | O40: B | P40: 홈페이지 확인
...

Sheet 진행현황
A1: 입력·검증 진행현황 (자동 집계)
A2: 단위: 건(면수는 면). 비율은 각 표의 합계 대비입니다.
A4: 사업장목록 | B4: 건수 | C4: 비율
A5: 전체 등록 건수 | B5: =COUNTA(사업장목록!$A$2:$A$151) -> 18
A7: 검증 상태 | B7: 건수 | C7: 비율
A8: 확인완료 | B8: =COUNTIF(사업장목록!$X$2:$X$151,"확인완료") -> 6 | C8: =IF($B$5=0,0,B8/$B$5) -> 0.33333333
A9: 홈페이지 확인 | B9: =COUNTIF(사업장목록!$X$2:$X$151,"홈페이지 확인") -> 12 | C9: =IF($B$5=0,0,B9/$B$5) -> 0.66666667
A10: 확인 필요 | B10: =COUNTIF(사업장목록!$X$2:$X$151,"확인 필요") -> 0 | C10: =IF($B$5=0,0,B10/$B$5) -> 0
A11: 출처 미확인 | B11: =COUNTIF(사업장목록!$X$2:$X$151,"출처 미확인") -> 0 | C11: =IF($B$5=0,0,B11/$B$5) -> 0
A12: 미입력 | B12: =COUNTIF(사업장목록!$X$2:$X$151,"미입력") -> 0 | C12: =IF($B$5=0,0,B12/$B$5) -> 0
A14: 공사 공식 분류 | B14: 건수 | C14: 비율
A15: 문화·체육 | B15: =COUNTIF(사업장목록!$C$2:$C$151,"문화·체육") -> 7 | C15: =IF($B$5=0,0,B15/$B$5) -> 0.38888889
A16: 생활·복지 | B16: =COUNTIF(사업장목록!$C$2:$C$151,"생활·복지") -> 4 | C16: =IF($B$5=0,0,B16/$B$5) -> 0.22222222
A17: 주차·교통 | B17: =COUNTIF(사업장목록!$C$2:$C$151,"주차·교통") -> 5 | C17: =IF($B$5=0,0,B17/$B$5) -> 0.27777778
A18: 개발사업 | B18: =COUNTIF(사업장목록!$C$2:$C$151,"개발사업") -> 1 | C18: =IF($B$5=0,0,B18/$B$5) -> 0.055555556
A19: 공사 본사 | B19: =COUNTIF(사업장목록!$C$2:$C$151,"공사 본사") -> 1 | C19: =IF($B$5=0,0,B19/$B$5) -> 0.055555556
A21: 생활목적 분류 | B21: 건수 | C21: 비율
A22: 운동·배우기 | B22: =COUNTIF(사업장목록!$D$2:$D$151,"운동·배우기") -> 6 | C22: =IF($B$5=0,0,B22/$B$5) -> 0.33333333
A23: 캠핑·여가 | B23: =COUNTIF(사업장목록!$D$2:$D$151,"캠핑·여가") -> 1 | C23: =IF($B$5=0,0,B23/$B$5) -> 0.055555556
A24: 장례·추모 | B24: =COUNTIF(사업장목록!$D$2:$D$151,"장례·추모") -> 1 | C24: =IF($B$5=0,0,B24/$B$5) -> 0.055555556
A25: 돌봄·복지 | B25: =COUNTIF(사업장목록!$D$2:$D$151,"돌봄·복지") -> 1 | C25: =IF($B$5=0,0,B25/$B$5) -> 0.055555556
A26: 이동 지원 | B26: =COUNTIF(사업장목록!$D$2:$D$151,"이동 지원") -> 1 | C26: =IF($B$5=0,0,B26/$B$5) -> 0.055555556
A27: 환경·자원순환 | B27: =COUNTIF(사업장목록!$D$2:$D$151,"환경·자원순환") -> 1 | C27: =IF($B$5=0,0,B27/$B$5) -> 0.055555556
A28: 주차하기 | B28: =COUNTIF(사업장목록!$D$2:$D$151,"주차하기") -> 2 | C28: =IF($B$5=0,0,B28/$B$5) -> 0.11111111
A29: 교통·차량 서비스 | B29: =COUNTIF(사업장목록!$D$2:$D$151,"교통·차량 서비스") -> 3 | C29: =IF($B$5=0,0,B29/$B$5) -> 0.16666667
A30: 공사 본사·개발사업 | B30: =COUNTIF(사업장목록!$D$2:$D$151,"공사 본사·개발사업") -> 2 | C30: =IF($B$5=0,0,B30/$B$5) -> 0.11111111
A32: 지도 표시 방식 | B32: 건수 | C32: 비율
A33: 시설 마커 | B33: =COUNTIF(사업장목록!$F$2:$F$151,"시설 마커") -> 14 | C33: =IF($B$5=0,0,B33/$B$5) -> 0.77777778
A34: 레이어 | B34: =COUNTIF(사업장목록!$F$2:$F$151,"레이어") -> 1 | C34: =IF($B$5=0,0,B34/$B$5) -> 0.055555556
A35: 서비스 안내 | B35: =COUNTIF(사업장목록!$F$2:$F$151,"서비스 안내") -> 3 | C35: =IF($B$5=0,0,B35/$B$5) -> 0.16666667
A37: 공영주차장 | B37: 개소 | C37: 면수
A38: 전체 | B38: =COUNTA(공영주차장!$A$2:$A$70) -> 69 | C38: =SUM(공영주차장!$F$2:$F$70) -> 10555
A39: 공영 | B39: =COUNTIF(공영주차장!$D$2:$D$70,"공영") -> 50 | C39: =SUMIF(공영주차장!$D$2:$D$70,"공영",공영주차장!$F$2:$F$70) -> 6590
A40: 부설 | B40: =COUNTIF(공영주차장!$D$2:$D$70,"부설") -> 12 | C40: =SUMIF(공영주차장!$D$2:$D$70,"부설",공영주차장!$F$2:$F$70) -> 2211
A41: 현장운영 | B41: =COUNTIF(공영주차장!$D$2:$D$70,"현장운영") -> 7 | C41: =SUMIF(공영주차장!$D$2:$D$70,"현장운영",공영주차장!$F$2:$F$70) -> 1754
A43: 주차장 검증 상태 | B43: 개소 | C43: 비율
A44: 홈페이지 확인 | B44: =COUNTIF(공영주차장!$P$2:$P$70,"홈페이지 확인") -> 51 | C44: =IF($B$38=0,0,B44/$B$38) -> 0.73913043
A45: 확인 필요 | B45: =COUNTIF(공영주차장!$P$2:$P$70,"확인 필요") -> 18 | C45: =IF($B$38=0,0,B45/$B$38) -> 0.26086957
A46: 확인완료 | B46: =COUNTIF(공영주차장!$P$2:$P$70,"확인완료") -> 0 | C46: =IF($B$38=0,0,B46/$B$38) -> 0

Sheet 분류코드
A1: 공사 공식 분류 | B1: 생활목적 분류 | C1: 지도 표시 방식 | D1: 구 | E1: 일러스트 등급 | F1: 검증 상태 | G1: 사진 확보
A2: 문화·체육 | B2: 운동·배우기 | C2: 시설 마커 | D2: 장안구 | E2: A | F2: 확인완료 | G2: 확보
A3: 생활·복지 | B3: 캠핑·여가 | C3: 레이어 | D3: 권선구 | E3: B | F3: 홈페이지 확인 | G3: 미확보
A4: 주차·교통 | B4: 장례·추모 | C4: 서비스 안내 | D4: 팔달구 | E4: - | F4: 확인 필요 | G4: 촬영 필요
A5: 개발사업 | B5: 돌봄·복지 | D5: 영통구 | F5: 출처 미확인
A6: 공사 본사 | B6: 이동 지원 | D6: 여러 구 | F6: 미입력
B7: 환경·자원순환 | D7: 수원시 외
B8: 주차하기 | D8: 확인 필요
B9: 교통·차량 서비스
B10: 공사 본사·개발사업
A22: ※ 공사 공식 분류는 공사 홈페이지 '사업현황' 탭(문화·체육/생활·복지/주차·교통/개발사업) 기준입니다. 생활목적 분류는 지도 필터용으로 기획팀이 정한 값입니다.
A23: ※ 드롭다운은 각 열 20행까지 인식하므로 빈 칸에 값을 추가하면 바로 반영됩니다.

Sheet 변경내역
A1: 구분 | B1: 대상 | C1: v0.1 | D1: v0.2 | E1: 근거
A2: 분류 체계 | B2: 전체 | C2: 생활목적 분류만 사용 | D2: 공사 공식 분류(4개 탭+본사) 열 추가, 생활목적 분류 9개로 세분화 | E2: 공사 홈페이지 사업현황
A3: 신규 추가 | B3: 광교호수가족캠핑장 | C3: 없음 | D3: 추가(문화·체육) | E3: 공사 홈페이지 사업현황
A4: 신규 추가 | B4: 수원시장기요양지원센터 | C4: 없음 | D4: 추가(생활·복지) | E4: 공사 홈페이지 사업현황
A5: 신규 추가 | B5: 거주자우선주차·견인보관소, 번호판제작소, 환승센터 2곳 | C5: 없음 | D5: 추가(주차·교통) | E5: 공사 홈페이지 사업현황
A6: 신규 추가 | B6: 수원도시공사 본사, 개발사업본부 | C6: 없음 | D6: 추가 | E6: 공사 홈페이지 하단·사업현황
A7: 통합 | B7: 더함파크 | C7: 분류 미정 사업장 | D7: 본사 사옥(수인로 126 더함파크 3층)으로 확인, 본사 행에 통합 | E7: 공사 홈페이지 하단
A8: 교체 | B8: 공영주차장 | C8: 2019년 기사 기준 45곳, 1행 | D8: 통합홈페이지 등록 69개소, 별도 시트(위도·경도 포함) | E8: 공영주차장 통합홈페이지
A9: 삭제 | B9: 팔달주차타워(지동시장) | C9: 2019년 기사 기준 포함 | D9: 현행 69개소 목록에 없어 제외 | E9: 공영주차장 통합홈페이지
A10: 통합 | B10: 농수산물도매시장 부설주차장 | C10: 별도 행 | D10: 공영주차장 시트 '농수산물도매시장'(현장운영)으로 이동 | E10: 공영주차장 통합홈페이지
A11: 정정 | B11: 화산체육공원 주소·구 | C11: 주소 미입력 | D11: 경기도 화성시 병점구 태안로 263, 구 '수원시 외' | E11: 화산체육공원 홈페이지 하단
A12: 정정 | B12: 대표전화(장안·종합운동장·칠보·웰빙) | C12: 수원시 자료 번호 | D12: 공사 홈페이지 번호로 입력, 수원시 자료 번호는 비고에 병기 | E12: 시설 홈페이지 하단
... A20: 보완 | B20: 운영시간·휴관일 17건 | C20: 대부분 미입력 | D20: 기획팀장 답변으로 입력(장안구민회관 시간은 카카오맵 값 확인) | E20: 기획팀장 확인 2026-10-29

Sheet 출처목록
A1: 자료명 | B1: 발행·관리 | C1: 확인일 | D1: 링크
A2: 수원도시공사 공사소개 > 사업현황 | B2: 수원도시공사 | C2: 2026-10-29 | D2: https://www.suwonudc.co.kr/PageLink.do?menuNo=050000&subMenuNo=050100&thirdMenuNo=050109&link=forward:/PageContent.do&tempParam1=&
A3: 수원도시공사 메인 및 시설별 홈페이지(하단 주소·전화, 메뉴 구성) | B3: 수원도시공사 | C3: 2026-10-29 | D3: https://www.suwonudc.co.kr/mainPage.do
A4: 화산체육공원 Par-3 9홀 재개장 안내(공지 2026-10-23) | B4: 수원도시공사 | C4: 2026-10-29 | D4: https://www.suwonudc.co.kr/mainPage.do
A5: 번호판제작소 현황 및 이용안내 | B5: 수원도시공사 주차사업처 | C5: 2026-10-29 | D5: https://www.suwonudc.co.kr/park/PageLink.do?link=forward:/PageContent.do&menuNo=040000&subMenuNo=040100&thirdMenuNo=
A6: 수원 공영주차장 통합홈페이지(주차장 검색 결과) | B6: 수원도시공사 | C6: 2026-10-29 | D6: https://parking.suwonudc.co.kr/
A7: 카카오맵 장소 검색(주소·장소 링크) | B7: 카카오 | C7: 2026-10-29 | D7: https://map.kakao.com/
A8: 수원시 체육시설 현황(수정 2025-12-15) | B8: 수원시 체육진흥과 | C8: 2026-10-29 | D8: https://www.suwon.go.kr/sw-www/deptHome/dep_tour/culture03/culture03_03/culture03_03_13.jsp
A9: 수원시 수영장 현황(수정 2026-07-31) | B9: 수원시 체육진흥과 | C9: 2026-10-29 | D9: https://www.suwon.go.kr/sw-www/deptHome/dep_tour/culture03/culture03_03/culture03_03_14.jsp
A10: 서수원칠보체육관 탁구장 예약 안내 | B10: 수원시 통합예약 | C10: 2026-10-29 | D10: https://www.suwon.go.kr/web/reserv/faci/view.do?seqNo=836
